/pfs/work7/workspace/scratch/ma_ssiu-myspace/teapot/1_optimized.py:41: DeprecationWarning: DataFrameGroupBy.apply operated on the grouping columns. This behavior is deprecated, and in a future version of pandas the grouping columns will be excluded from the operation. Either pass `include_groups=False` to exclude the groupings or explicitly select the grouping columns after groupby to silence this warning.
  sampled_occupation = occupations.groupby("ind").apply(lambda x: x.sample(frac=0.05, random_state=1)).reset_index(drop=True)
2025-03-23 23:30:15,306 - INFO - Script started
2025-03-23 23:30:15,306 - INFO - Processing model: deepseek-r1
2025-03-23 23:30:15,320 - DEBUG - connect_tcp.started host='127.0.0.1' port=12312 local_address=None timeout=None socket_options=None
2025-03-23 23:30:15,320 - DEBUG - connect_tcp.failed exception=ConnectError(ConnectionRefusedError(111, 'Connection refused'))
Traceback (most recent call last):
  File "/pfs/work7/workspace/scratch/ma_ssiu-myspace/.conda/envs/test/lib/python3.11/site-packages/httpx/_transports/default.py", line 101, in map_httpcore_exceptions
    yield
  File "/pfs/work7/workspace/scratch/ma_ssiu-myspace/.conda/envs/test/lib/python3.11/site-packages/httpx/_transports/default.py", line 250, in handle_request
    resp = self._pool.handle_request(req)
           ^^^^^^^^^^^^^^^^^^^^^^^^^^^^^^
  File "/pfs/work7/workspace/scratch/ma_ssiu-myspace/.conda/envs/test/lib/python3.11/site-packages/httpcore/_sync/connection_pool.py", line 256, in handle_request
    raise exc from None
  File "/pfs/work7/workspace/scratch/ma_ssiu-myspace/.conda/envs/test/lib/python3.11/site-packages/httpcore/_sync/connection_pool.py", line 236, in handle_request
    response = connection.handle_request(
               ^^^^^^^^^^^^^^^^^^^^^^^^^^
  File "/pfs/work7/workspace/scratch/ma_ssiu-myspace/.conda/envs/test/lib/python3.11/site-packages/httpcore/_sync/connection.py", line 101, in handle_request
    raise exc
  File "/pfs/work7/workspace/scratch/ma_ssiu-myspace/.conda/envs/test/lib/python3.11/site-packages/httpcore/_sync/connection.py", line 78, in handle_request
    stream = self._connect(request)
             ^^^^^^^^^^^^^^^^^^^^^^
  File "/pfs/work7/workspace/scratch/ma_ssiu-myspace/.conda/envs/test/lib/python3.11/site-packages/httpcore/_sync/connection.py", line 124, in _connect
    stream = self._network_backend.connect_tcp(**kwargs)
             ^^^^^^^^^^^^^^^^^^^^^^^^^^^^^^^^^^^^^^^^^^^
  File "/pfs/work7/workspace/scratch/ma_ssiu-myspace/.conda/envs/test/lib/python3.11/site-packages/httpcore/_backends/sync.py", line 207, in connect_tcp
    with map_exceptions(exc_map):
  File "/pfs/work7/workspace/scratch/ma_ssiu-myspace/.conda/envs/test/lib/python3.11/contextlib.py", line 158, in __exit__
    self.gen.throw(typ, value, traceback)
  File "/pfs/work7/workspace/scratch/ma_ssiu-myspace/.conda/envs/test/lib/python3.11/site-packages/httpcore/_exceptions.py", line 14, in map_exceptions
    raise to_exc(exc) from exc
httpcore.ConnectError: [Errno 111] Connection refused

The above exception was the direct cause of the following exception:

Traceback (most recent call last):
  File "/pfs/work7/workspace/scratch/ma_ssiu-myspace/teapot/1_optimized.py", line 195, in <module>
    main()
  File "/pfs/work7/workspace/scratch/ma_ssiu-myspace/teapot/1_optimized.py", line 156, in main
    warmup_model.invoke("Warm-up prompt")
  File "/pfs/work7/workspace/scratch/ma_ssiu-myspace/.conda/envs/test/lib/python3.11/site-packages/langchain_core/language_models/chat_models.py", line 307, in invoke
    self.generate_prompt(
  File "/pfs/work7/workspace/scratch/ma_ssiu-myspace/.conda/envs/test/lib/python3.11/site-packages/langchain_core/language_models/chat_models.py", line 843, in generate_prompt
    return self.generate(prompt_messages, stop=stop, callbacks=callbacks, **kwargs)
           ^^^^^^^^^^^^^^^^^^^^^^^^^^^^^^^^^^^^^^^^^^^^^^^^^^^^^^^^^^^^^^^^^^^^^^^^
  File "/pfs/work7/workspace/scratch/ma_ssiu-myspace/.conda/envs/test/lib/python3.11/site-packages/langchain_core/language_models/chat_models.py", line 683, in generate
    self._generate_with_cache(
  File "/pfs/work7/workspace/scratch/ma_ssiu-myspace/.conda/envs/test/lib/python3.11/site-packages/langchain_core/language_models/chat_models.py", line 908, in _generate_with_cache
    result = self._generate(
             ^^^^^^^^^^^^^^^
  File "/pfs/work7/workspace/scratch/ma_ssiu-myspace/.conda/envs/test/lib/python3.11/site-packages/langchain_ollama/chat_models.py", line 701, in _generate
    final_chunk = self._chat_stream_with_aggregation(
                  ^^^^^^^^^^^^^^^^^^^^^^^^^^^^^^^^^^^
  File "/pfs/work7/workspace/scratch/ma_ssiu-myspace/.conda/envs/test/lib/python3.11/site-packages/langchain_ollama/chat_models.py", line 602, in _chat_stream_with_aggregation
    for stream_resp in self._create_chat_stream(messages, stop, **kwargs):
  File "/pfs/work7/workspace/scratch/ma_ssiu-myspace/.conda/envs/test/lib/python3.11/site-packages/langchain_ollama/chat_models.py", line 589, in _create_chat_stream
    yield from self._client.chat(**chat_params)
  File "/pfs/work7/workspace/scratch/ma_ssiu-myspace/.conda/envs/test/lib/python3.11/site-packages/ollama/_client.py", line 163, in inner
    with self._client.stream(*args, **kwargs) as r:
  File "/pfs/work7/workspace/scratch/ma_ssiu-myspace/.conda/envs/test/lib/python3.11/contextlib.py", line 137, in __enter__
    return next(self.gen)
           ^^^^^^^^^^^^^^
  File "/pfs/work7/workspace/scratch/ma_ssiu-myspace/.conda/envs/test/lib/python3.11/site-packages/httpx/_client.py", line 868, in stream
    response = self.send(
               ^^^^^^^^^^
  File "/pfs/work7/workspace/scratch/ma_ssiu-myspace/.conda/envs/test/lib/python3.11/site-packages/httpx/_client.py", line 914, in send
    response = self._send_handling_auth(
               ^^^^^^^^^^^^^^^^^^^^^^^^^
  File "/pfs/work7/workspace/scratch/ma_ssiu-myspace/.conda/envs/test/lib/python3.11/site-packages/httpx/_client.py", line 942, in _send_handling_auth
    response = self._send_handling_redirects(
               ^^^^^^^^^^^^^^^^^^^^^^^^^^^^^^
  File "/pfs/work7/workspace/scratch/ma_ssiu-myspace/.conda/envs/test/lib/python3.11/site-packages/httpx/_client.py", line 979, in _send_handling_redirects
    response = self._send_single_request(request)
               ^^^^^^^^^^^^^^^^^^^^^^^^^^^^^^^^^^
  File "/pfs/work7/workspace/scratch/ma_ssiu-myspace/.conda/envs/test/lib/python3.11/site-packages/httpx/_client.py", line 1014, in _send_single_request
    response = transport.handle_request(request)
               ^^^^^^^^^^^^^^^^^^^^^^^^^^^^^^^^^
  File "/pfs/work7/workspace/scratch/ma_ssiu-myspace/.conda/envs/test/lib/python3.11/site-packages/httpx/_transports/default.py", line 249, in handle_request
    with map_httpcore_exceptions():
  File "/pfs/work7/workspace/scratch/ma_ssiu-myspace/.conda/envs/test/lib/python3.11/contextlib.py", line 158, in __exit__
    self.gen.throw(typ, value, traceback)
  File "/pfs/work7/workspace/scratch/ma_ssiu-myspace/.conda/envs/test/lib/python3.11/site-packages/httpx/_transports/default.py", line 118, in map_httpcore_exceptions
    raise mapped_exc(message) from exc
httpx.ConnectError: [Errno 111] Connection refused
/var/spool/slurmd/job25411878/slurm_script: line 56: kill: (374507) - No such process
